Workbook

Sheet Pendências
A1: Cruzamento da pasta Tesouraria com as pendências do escritório (saldo de 31/08/2026)
A2: Levantamento de 13/10/2026, somente leitura. Cada arquivo foi achado por valor, data, fornecedor e número da NF; os PDFs com texto tiveram o conteúdo lido. Imagens e PDFs escaneados: só nome e valor conferidos.
A3: ID | B3: Grupo | C3: Conta | D3: Data | E3: Valor (R$) | F3: Pendência | G3: Documento encontrado? | H3: NF encontrada? | I3: Comprovante encontrado? | J3: Contrato encontrado? | K3: Justificativa encontrada? | L3: Resposta já dada ao escritório? | M3: Classificação | N3: Arquivo(s) da pasta | O3: Observação e próximo passo
A4: AP-01 | B4: Ativo em Processamento | C4: 100165 | D4: 46034.625 | E4: 114.95 | F4: Festa Mania Tijuca (cartão) | G4: Não | H4: Não | I4: Sim | J4: não se aplica | K4: Não | L4: Não | M4: Falta Documento | N4: JAN.2026 _ FATURA CARTÃO.PDF | O4: A fatura do cartão de jan/2026 existe (prova o gasto), mas a NF da Festa Mania Tijuca não está na pasta. Pedir a NF à loja.
A5: AP-02 | B5: Ativo em Processamento | C5: 100165 | D5: 46037.625 | E5: 215.08 | F5: Light | G5: Sim | H5: não se aplica | I5: Sim | J5: não se aplica | K5: não se aplica | L5: Sim | M5: Resolvida | N5: 15.01.2026 - R$215,08 _ FATURA LIGHT _ SENADOR FURTADO _ PG BANKLINE.pdf | O5: Fatura da Light com comprovante. Já respondida na planilha de jan/2026 (aba BRADESCO).
A6: AP-03 | B6: Ativo em Processamento | C6: 100165 | D6: 46063.625 | E6: 2308.56 | F6: Hoteis.com parc. 1/4 (cartão) | G6: Parcial | H6: Não | I6: Sim | J6: não se aplica | K6: Não | L6: Não | M6: Parcialmente Resolvida | N6: 10.02.2026 - R$577,14 _ HOTEIS COM _ 1.4 _ PG VISA.pdf 10.03.2026 - R$577,13 _ HOTEIS COM _ 2.4 _ PG VISA.pdf 10.04.2026 - R$577,13 _ HOTEIS COM _ 3.4 _ PG VISA.pdf 10.05.2026 - R$577,13 _ HOTEIS COM _ 4.4 _ PG VISA.pdf | O6: Comprovantes das 4 parcelas (577,14 + 3 × 577,13 = 2.308,53; diferença de R$ 0,03). São imagens: valor e nome conferem, o conteúdo não foi lido. Falta a NF ou o voucher do Hoteis.com.
A7: AP-04 | B7: Ativo em Processamento | C7: 100165 | D7: 46063.625 | E7: 1541.4 | F7: Latam parc. 1/4 (cartão) | G7: Não | H7: Não | I7: Sim | J7: não se aplica | K7: Não | L7: Não | M7: Falta Documento | N7: — | O7: Nada da Latam em fev/2026. Os dois JPEGs da Latam (R$ 2.392,00 e R$ 269,00) são de setembro, de outra viagem. Falta o bilhete ou recibo.
A8: AP-05 | B8: Ativo em Processamento | C8: 100165 | D8: 46063.625 | E8: 400 | F8: S2P inscrição 1/2 (cartão) (1) | G8: Não | H8: Não | I8: Sim | J8: não se aplica | K8: Não | L8: Não | M8: Falta Documento | N8: — | O8: Nada da S2P/E-Inscrição na pasta. Falta o comprovante ou a NF da inscrição (2 inscrições, 2 parcelas de R$ 200,00 cada).
A9: AP-06 | B9: Ativo em Processamento | C9: 100165 | D9: 46063.625 | E9: 400 | F9: S2P inscrição 1/2 (cartão) (2) | G9: Não | H9: Não | I9: Sim | J9: não se aplica | K9: Não | L9: Não | M9: Falta Documento | N9: — | O9: Idem AP-05 (segunda inscrição).
A10: AP-07 | B10: Ativo em Processamento | C10: 100165 | D10: 46063.625 | E10: 232.5 | F10: Zupper (cartão) | G10: Não | H10: Não | I10: Sim | J10: não se aplica | K10: Não | L10: Não | M10: Falta Documento | N10: — | O10: Nada da Zupper (emitente no app: Kontik Franstur). Falta a NF.
A11: AP-08 | B11: Ativo em Processamento | C11: 100165 | D11: 46076.625 | E11: 1000 | F11: Commander Digital | G11: Não | H11: Não | I11: Não | J11: não se aplica | K11: Não | L11: Não | M11: Falta Documento | N11: — | O11: Só existem a fatura da Commander de 23/01 (R$ 1.000,00) e o pagamento de R$ 500,00 de 27/02. Falta a fatura de fevereiro.
A12: AP-09 | B12: Ativo em Processamento | C12: 100165 | D12: 46083.625 | E12: 321.62 | F12: Flora Energia | G12: Sim | H12: não se aplica | I12: Sim | J12: não se aplica | K12: não se aplica | L12: Sim | M12: Resolvida | N12: 02.03.2026 - R$321,62 _ FLORA ENERGIA _ PG BANKLINE.pdf 02.03.2026 - R$321,62 _ FLORA ENERGIA _ PG BANKLINE.pdf | O12: Boleto da Flora (via IUGU) com comprovante; o valor confere no texto. Já está na pasta Pendências AL.
A13: AP-10 | B13: Ativo em Processamento | C13: 100165 | D13: 46098.625 | E13: 221.38 | F13: Flora Energia | G13: Sim | H13: não se aplica | I13: Sim | J13: não se aplica | K13: não se aplica | L13: Sim | M13: Resolvida | N13: 17.03.2026 - R$221,38 _ FLORA _ FATURA _ PG BANKLINE.pdf 17.03.2026 - R$221,38 _ FLORA _ FATURA _ PG BANKLINE.pdf | O13: Fatura da Flora com comprovante; valor confere no texto. Já está na pasta Pendências AL.
A14: AP-11 | B14: Ativo em Processamento | C14: 100165 | D14: 46105.625 | E14: 1000 | F14: Commander Digital | G14: Não | H14: Não | I14: Não | J14: não se aplica | K14: Não | L14: Não | M14: Falta Documento | N14: — | O14: Nada da Commander em março. Falta a fatura.
A15: AP-12 | B15: Ativo em Processamento | C15: 100165 | D15: 46122.625 | E15: 59.8 | F15: Prodesc Benfica (cartão) | G15: Sim | H15: Sim | I15: Sim | J15: não se aplica | K15: não se aplica | L15: Não | M15: Resolvida | N15: 10.04.2026 - R$59,80 _ PRODESC BENFICA _ PG CARTAO.pdf | O15: NF-e do consumidor nº 125233, R$ 59,80, emitida em 02/03/2026 pela Prodesc Benfica (CNPJ 06.058.769/0001-47). Fatura do cartão de abril existe.
... A63: TC-01 | B63: Título de Capitalização | C63: 122006 | D63: 46265.625 | E63: 4577.76 | F63: Título de Capitalização Bradesco (proposta 50213007/2): contrato e parcelas | G63: Parcial | H63: não se aplica | I63: Sim | J63: Não | K63: Não | L63: Não | M63: Parcialmente Resolvida | N63: EXTRATO BRADESCO FEV.2023.PDF Extrato Bradesco 03_2023.pdf EXTRATO BRADESCO MAIO.2023.PDF 03.06.2024 - R$104,64 _ TÍTULO DE CAPITALIZAÇÃO BRADESCO _ PG BANKLINE.pdf 03.06.2025 - R$109,92 _ TITULO DE CAPITALIZAÇÃO _ PG BANKLINE.pdf | O63: Conferi no texto os extratos de fev a dez/2023 (todos mostram o débito do título); os extratos de 2024 a 2026 estão na pasta, e há 5 comprovantes avulsos. NÃO existe contrato nem a proposta 50213007/2 na pasta, nem a explicação da mudança de 60 para 90 parcelas.
A64: CT-01 | B64: Cartão de crédito a pagar | C64: 211998 | E64: 5635.38 | F64: NF 666342: Frigelar (07x08) | G64: Parcial | H64: Sim | I64: Sim | J64: não se aplica | K64: Não | L64: Não | M64: Parcialmente Resolvida | N64: 10.06.2025 - R$704,44 _ NF666342 _ FRIGELAR COMERCIO E INDUSTRIA LTDA _ PG CARTÃO DE CRÉDITO 9738.pdf 10.08.2025 - R$704,42 _ NF666342 _ FRIGELAR COMERCIO E INDUSTRIA LTDA _ 3_08 _ PG CARTÃO.pdf | O64: 7 de 8 parcelas da NF 666342 (Frigelar) com comprovante: jun, ago, set, out, nov, dez/2025 e jan/2026. Falta a parcela 2/8 (jul/2025). Um 8º arquivo com esse número de NF é da Convicção Editora, outra compra.
A65: CT-02 | B65: Cartão de crédito a pagar | C65: 211998 | E65: 4241.38 | F65: NF 171742: BMB Material de Construção (06x06) | G65: Parcial | H65: Parcial | I65: Sim | J65: não se aplica | K65: Não | L65: Não | M65: Parcialmente Resolvida | N65: 10.09.2025 - R$706,93 _ NF141742 _ BMB MATERIAL DE CONSTRUCAO SA _ PARCELA 01.06 _ PG CARTAO.pdf | O65: 4 de 6 parcelas (set a dez/2025). O nº da NF nos arquivos é 141742, o escritório diz 171742 (um dos dois está digitado errado). Faltam as parcelas de jan e fev/2026.
A66: CT-03 | B66: Cartão de crédito a pagar | C66: 211998 | E66: 400 | F66: NF S2P-1: S2P/E-Inscrição inscrição 1 (01x02) | G66: Não | H66: Não | I66: Não | J66: não se aplica | K66: Não | L66: Não | M66: Falta Documento | N66: — | O66: Nada na pasta (ver AP-05).
A67: CT-04 | B67: Cartão de crédito a pagar | C67: 211998 | E67: 400 | F67: NF S2P-2: S2P/E-Inscrição inscrição 2 (01x02) | G67: Não | H67: Não | I67: Não | J67: não se aplica | K67: Não | L67: Não | M67: Falta Documento | N67: — | O67: Nada na pasta (ver AP-06).
A68: CT-05 | B68: Cartão de crédito a pagar | C68: 211998 | E68: 754.56 | F68: NF 45298: MP Store (05x06) | G68: Sim | H68: Sim | I68: Sim | J68: não se aplica | K68: não se aplica | L68: Não | M68: Resolvida | N68: 10.03.2026 - R$125,76 _ NF45298 _ MP STORE COMERCIAL LTDA _ 1_6 _ PG VISA.pdf | O68: 6 de 6 parcelas com NF e comprovante.
A69: CT-06 | B69: Cartão de crédito a pagar | C69: 211998 | E69: 145.84 | F69: NF 22423: Lojão do Alcântara (03x04) | G69: Sim | H69: Sim | I69: Sim | J69: não se aplica | K69: não se aplica | L69: Não | M69: Resolvida | N69: 10.04.2026 - R$36,46 _ NF22423 _ LOJA DO ALCANTARA ELETRONICA LTDA _ 1_4 _ PG VISA.pdf | O69: 4 de 4 parcelas com NF e comprovante.
A70: CT-07 | B70: Cartão de crédito a pagar | C70: 211998 | E70: 519.98 | F70: NF 1931: G2B Comércio (05x06) = Prisma | G70: Parcial | H70: Parcial | I70: Sim | J70: não se aplica | K70: Não | L70: Não | M70: Parcialmente Resolvida | N70: 10.05.2026 - R$86,66 _ NF000.005.362 _ PRISMA COMERCIO VAREJISTA E ATACADISTA LTDA _ 02_06 _ PG VISA.pdf | O70: 6 parcelas de R$ 86,66 com NF, mas a NF nos arquivos é a 5362 da Prisma, e o escritório fala da NF 1931 da G2B. Confirmar se é a mesma compra.
A71: CT-08 | B71: Cartão de crédito a pagar | C71: 211998 | E71: 44.4 | F71: NF 14316: André Pereira (02x02) | G71: Não | H71: Não | I71: Não | J71: não se aplica | K71: Não | L71: Não | M71: Falta Documento | N71: — | O71: Nada do André Pereira (NF 14316) na pasta.
A72: CT-09 | B72: Cartão de crédito a pagar | C72: 211998 | E72: 110 | F72: NF 1108: Guirão Distribuidora de Som (03x04) | G72: Sim | H72: Sim | I72: Sim | J72: não se aplica | K72: não se aplica | L72: Não | M72: Resolvida | N72: 10.04.2026 - R$27,50 _ NF1.108 _ GUIRAO DISTRIBUIDORA DE SOM ACESSORIOS LTDA _ 1_4 _ PG VISA.pdf | O72: 4 de 4 parcelas com NF e comprovante.
A73: CT-10 | B73: Cartão de crédito a pagar | C73: 211998 | E73: 519.8 | F73: NF 9370: Modamusicnet (05x10) | G73: Sim | H73: Sim | I73: Sim | J73: não se aplica | K73: não se aplica | L73: Não | M73: Resolvida | N73: 10.04.2026 - R$51,98 _ NF9.370 _ MODAMUSICNET LTDA _ 01_10 _ PG VISA.pdf | O73: 10 de 10 parcelas com NF e comprovante (5 delas após 31/08).
A74: CT-11 | B74: Cartão de crédito a pagar | C74: 211998 | E74: 1299 | F74: NF 311998: Login Informática (04x10) | G74: Sim | H74: Sim | I74: Sim | J74: não se aplica | K74: não se aplica | L74: Não | M74: Resolvida | N74: 10.05.2026 - R$129,90 _ NF311.998 _ LOGIN INFORMATICA COMERCIO E REPRESENTACAO LTDA _ 01_10 _ PG VISA.pdf | O74: 10 de 10 parcelas com NF e comprovante.
A75: CT-12 | B75: Cartão de crédito a pagar | C75: 211998 | E75: 1899 | F75: NF 1612586: TNTInfo (05x10) | G75: Sim | H75: Sim | I75: Sim | J75: não se aplica | K75: não se aplica | L75: Não | M75: Resolvida | N75: 10.05.2026 - R$189,90 _ NF1.612.586 _ TNTINFO COMERCIO DE MATERIAIS DE INFORMATICA LTDA _ 01_10 _ PG VISA.pdf | O75: 10 de 10 parcelas com NF e comprovante.
... A85: CT-22 | B85: Cartão de crédito a pagar | C85: 211998 | E85: 4958.2 | F85: NF 776588: BMB/Obramax (01x05) | G85: Sim | H85: Sim | I85: Sim | J85: não se aplica | K85: não se aplica | L85: Não | M85: Resolvida | N85: 10.08.2026 - R$991,64 _ NF000776588 _ BMB MATERIAL DE CONSTRUCAO _ PG VISA.pdf | O85: NF e 1ª parcela (ago/2026) com comprovante. As demais vencem depois de 31/08.
A86: CT-23 | B86: Cartão de crédito a pagar | C86: 211998 | D86: 46183.625 | E86: 3746.42 | F86: Fatura do cartão de junho/2026 (paga em 10/06) | G86: Não | H86: não se aplica | I86: Não | J86: não se aplica | K86: Não | L86: Não | M86: Falta Documento | N86: — | O86: Faturas do cartão existem em jan, fev, mar, abr, mai, jul e ago/2026; a de JUNHO (paga em 10/06, R$ 3.746,42) não está na pasta. Há os 14 comprovantes e NFs das compras de junho.
A87: FB-01 | B87: Fornecedores de bens | C87: 211005 | D87: 45955.625 | E87: 125.88 | F87: NF 6942: RFC Comércio de Miudezas | G87: Não | H87: Não | I87: Não | J87: não se aplica | K87: Não | L87: Não | M87: Falta Decisão da Igreja | N87: — | O87: Nenhum registro do RFC na pasta. A NF foi emitida no CNPJ da igreja. Decidir: oferta, reembolso, pago de outra forma ou investigar.
A88: FB-02 | B88: Fornecedores de bens | C88: 211005 | D88: 45957.625 | E88: 84.2 | F88: NF 344169: Kalunga | G88: Não | H88: Não | I88: Não | J88: não se aplica | K88: Não | L88: Não | M88: Falta Decisão da Igreja | N88: — | O88: Nenhum registro da Kalunga na pasta. Decidir (ver FB-01).
A89: FB-03 | B89: Fornecedores de bens | C89: 211005 | D89: 45958.625 | E89: 25 | F89: NF 64: Vira Verão Bazar | G89: Não | H89: Não | I89: Não | J89: não se aplica | K89: Não | L89: Não | M89: Falta Decisão da Igreja | N89: — | O89: Nenhum registro da Vira Verão na pasta. Decidir (ver FB-01).
A90: FB-04 | B90: Fornecedores de bens | C90: 211005 | D90: 45959.625 | E90: 25.98 | F90: NF 66: Estação da Central | G90: Não | H90: Não | I90: Não | J90: não se aplica | K90: Não | L90: Não | M90: Falta Decisão da Igreja | N90: — | O90: Nenhum registro da Estação da Central na pasta. Decidir (ver FB-01).
A91: FB-05 | B91: Fornecedores de bens | C91: 211005 | D91: 45980.625 | E91: 112.22 | F91: NF 31606: Claudinei Pinhal dos Santos | G91: Não | H91: Não | I91: Não | J91: não se aplica | K91: Não | L91: Não | M91: Falta Decisão da Igreja | N91: — | O91: Nenhum registro do Claudinei Pinhal na pasta. Decidir (ver FB-01).
A92: FB-06 | B92: Fornecedores de bens | C92: 211005 | D92: 46130.625 | E92: 143 | F92: NF 3763: SOS Sobrado Malhas | G92: Não | H92: Não | I92: Não | J92: não se aplica | K92: Não | L92: Não | M92: Falta Decisão da Igreja | N92: — | O92: Nenhum registro da SOS Sobrado na pasta. Decidir (ver FB-01).
A93: FB-07 | B93: Fornecedores de bens | C93: 211005 | D93: 46140.625 | E93: 104.4 | F93: NF 9922: Tech Brasil | G93: Não | H93: Não | I93: Não | J93: não se aplica | K93: Não | L93: Não | M93: Falta Decisão da Igreja | N93: — | O93: Nenhum registro da Tech Brasil na pasta. Decidir (ver FB-01).
A94: FB-08 | B94: Fornecedores de bens | C94: 211005 | D94: 46244.625 | E94: 255.3 | F94: NF 24553: Del Castilho Madeiras | G94: Sim | H94: Sim | I94: Sim | J94: não se aplica | K94: Sim | L94: Não | M94: Resolvida | N94: 10.08.2026 - R$255,30 _ NF24553 _ DEL CASTILHO MADEIRAS E CONSTRUCOES _ PG ESPECIE.pdf | O94: NF 24553 paga em espécie em 10/08/2026 (Caixa Auxiliar), valor confere no texto. Não consta no app como pagamento: precisa ser lançado no app.
A95: FB-09 | B95: Fornecedores de bens | C95: 211005 | D95: 46260.625 | E95: 149.38 | F95: NF 53836: C Cadamuro | G95: Não | H95: Não | I95: Não | J95: não se aplica | K95: Não | L95: Não | M95: Falta Decisão da Igreja | N95: — | O95: Nenhum registro da Cadamuro na pasta. Decidir (ver FB-01).
A96: FB-10 | B96: Fornecedores de bens | C96: 211005 | D96: 46265.625 | E96: 443.95 | F96: NF 1621752: Goldensky | G96: Não | H96: Não | I96: Não | J96: não se aplica | K96: Não | L96: Não | M96: Falta Decisão da Igreja | N96: — | O96: Nenhum registro da Goldensky na pasta. Decidir (ver FB-01).
...

Sheet Resumo
A1: Resumo: quantas pendências cada classificação resolve
A3: Grupo | B3: Resolvida | C3: Parcialmente Resolvida | D3: Falta Documento | E3: Falta Decisão da Igreja | F3: Falta Resposta à Contabilidade | G3: Total
A4: Ativo em Processamento | B4: =COUNTIFS(Pendências!$B$4:$B$138,$A4,Pendências!$M$4:$M$138,"Resolvida") | C4: =COUNTIFS(Pendências!$B$4:$B$138,$A4,Pendências!$M$4:$M$138,"Parcialmente Resolvida") | D4: =COUNTIFS(Pendências!$B$4:$B$138,$A4,Pendências!$M$4:$M$138,"Falta Documento") | E4: =COUNTIFS(Pendências!$B$4:$B$138,$A4,Pendências!$M$4:$M$138,"Falta Decisão da Igreja") | F4: =COUNTIFS(Pendências!$B$4:$B$138,$A4,Pendências!$M$4:$M$138,"Falta Resposta à Contabilidade") | G4: =SUM(B4:F4)
A5: Adiantamentos | B5: =COUNTIFS(Pendências!$B$4:$B$138,$A5,Pendências!$M$4:$M$138,"Resolvida") | C5: =COUNTIFS(Pendências!$B$4:$B$138,$A5,Pendências!$M$4:$M$138,"Parcialmente Resolvida") | D5: =COUNTIFS(Pendências!$B$4:$B$138,$A5,Pendências!$M$4:$M$138,"Falta Documento") | E5: =COUNTIFS(Pendências!$B$4:$B$138,$A5,Pendências!$M$4:$M$138,"Falta Decisão da Igreja") | F5: =COUNTIFS(Pendências!$B$4:$B$138,$A5,Pendências!$M$4:$M$138,"Falta Resposta à Contabilidade") | G5: =SUM(B5:F5)
A6: Título de Capitalização | B6: =COUNTIFS(Pendências!$B$4:$B$138,$A6,Pendências!$M$4:$M$138,"Resolvida") | C6: =COUNTIFS(Pendências!$B$4:$B$138,$A6,Pendências!$M$4:$M$138,"Parcialmente Resolvida") | D6: =COUNTIFS(Pendências!$B$4:$B$138,$A6,Pendências!$M$4:$M$138,"Falta Documento") | E6: =COUNTIFS(Pendências!$B$4:$B$138,$A6,Pendências!$M$4:$M$138,"Falta Decisão da Igreja") | F6: =COUNTIFS(Pendências!$B$4:$B$138,$A6,Pendências!$M$4:$M$138,"Falta Resposta à Contabilidade") | G6: =SUM(B6:F6)
A7: Cartão de crédito a pagar | B7: =COUNTIFS(Pendências!$B$4:$B$138,$A7,Pendências!$M$4:$M$138,"Resolvida") | C7: =COUNTIFS(Pendências!$B$4:$B$138,$A7,Pendências!$M$4:$M$138,"Parcialmente Resolvida") | D7: =COUNTIFS(Pendências!$B$4:$B$138,$A7,Pendências!$M$4:$M$138,"Falta Documento") | E7: =COUNTIFS(Pendências!$B$4:$B$138,$A7,Pendências!$M$4:$M$138,"Falta Decisão da Igreja") | F7: =COUNTIFS(Pendências!$B$4:$B$138,$A7,Pendências!$M$4:$M$138,"Falta Resposta à Contabilidade") | G7: =SUM(B7:F7)
A8: Fornecedores de bens | B8: =COUNTIFS(Pendências!$B$4:$B$138,$A8,Pendências!$M$4:$M$138,"Resolvida") | C8: =COUNTIFS(Pendências!$B$4:$B$138,$A8,Pendências!$M$4:$M$138,"Parcialmente Resolvida") | D8: =COUNTIFS(Pendências!$B$4:$B$138,$A8,Pendências!$M$4:$M$138,"Falta Documento") | E8: =COUNTIFS(Pendências!$B$4:$B$138,$A8,Pendências!$M$4:$M$138,"Falta Decisão da Igreja") | F8: =COUNTIFS(Pendências!$B$4:$B$138,$A8,Pendências!$M$4:$M$138,"Falta Resposta à Contabilidade") | G8: =SUM(B8:F8)
A9: Fornecedores de serviços | B9: =COUNTIFS(Pendências!$B$4:$B$138,$A9,Pendências!$M$4:$M$138,"Resolvida") | C9: =COUNTIFS(Pendências!$B$4:$B$138,$A9,Pendências!$M$4:$M$138,"Parcialmente Resolvida") | D9: =COUNTIFS(Pendências!$B$4:$B$138,$A9,Pendências!$M$4:$M$138,"Falta Documento") | E9: =COUNTIFS(Pendências!$B$4:$B$138,$A9,Pendências!$M$4:$M$138,"Falta Decisão da Igreja") | F9: =COUNTIFS(Pendências!$B$4:$B$138,$A9,Pendências!$M$4:$M$138,"Falta Resposta à Contabilidade") | G9: =SUM(B9:F9)
A10: Outras pendências | B10: =COUNTIFS(Pendências!$B$4:$B$138,$A10,Pendências!$M$4:$M$138,"Resolvida") | C10: =COUNTIFS(Pendências!$B$4:$B$138,$A10,Pendências!$M$4:$M$138,"Parcialmente Resolvida") | D10: =COUNTIFS(Pendências!$B$4:$B$138,$A10,Pendências!$M$4:$M$138,"Falta Documento") | E10: =COUNTIFS(Pendências!$B$4:$B$138,$A10,Pendências!$M$4:$M$138,"Falta Decisão da Igreja") | F10: =COUNTIFS(Pendências!$B$4:$B$138,$A10,Pendências!$M$4:$M$138,"Falta Resposta à Contabilidade") | G10: =SUM(B10:F10)
A11: Total | B11: =SUM(B4:B10) | C11: =SUM(C4:C10) | D11: =SUM(D4:D10) | E11: =SUM(E4:E10) | F11: =SUM(F4:F10) | G11: =SUM(G4:G10)
A12: % do total | B12: =B11/$G$11 | C12: =C11/$G$11 | D12: =D11/$G$11 | E12: =E11/$G$11 | F12: =F11/$G$11
A14: Valor das pendências por classificação (R$)
A15: Resolvida | B15: =SUMIFS(Pendências!$E$4:$E$138,Pendências!$M$4:$M$138,A15)
A16: Parcialmente Resolvida | B16: =SUMIFS(Pendências!$E$4:$E$138,Pendências!$M$4:$M$138,A16)
A17: Falta Documento | B17: =SUMIFS(Pendências!$E$4:$E$138,Pendências!$M$4:$M$138,A17)
A18: Falta Decisão da Igreja | B18: =SUMIFS(Pendências!$E$4:$E$138,Pendências!$M$4:$M$138,A18)
A19: Falta Resposta à Contabilidade | B19: =SUMIFS(Pendências!$E$4:$E$138,Pendências!$M$4:$M$138,A19)
A20: Atenção: o valor soma o total de cada NF ou pendência; parcelas de cartão e NFs que aparecem duas vezes (adiantamento e fornecedor) entram nos dois grupos.

Sheet Para enviar ao escritório
A1: Resolvidas: o que já dá para mandar ao escritório (arquivos dentro da pasta Tesouraria)
A3: ID | B3: Grupo | C3: Pendência | D3: Arquivo(s) a enviar | E3: Caminho dentro do ZIP | F3: Observação
A4: AP-02 | B4: Ativo em Processamento | C4: Light | D4: 15.01.2026 - R$215,08 _ FATURA LIGHT _ SENADOR FURTADO _ PG BANKLINE.pdf | E4: Pendências AL/BRADESCO/15.01.2026 - R$215,08 _ FATURA LIGHT _ SENADOR FURTADO _ PG BANKLINE.pdf | F4: Fatura da Light com comprovante. Já respondida na planilha de jan/2026 (aba BRADESCO).
A5: AP-09 | B5: Ativo em Processamento | C5: Flora Energia | D5: 02.03.2026 - R$321,62 _ FLORA ENERGIA _ PG BANKLINE.pdf 02.03.2026 - R$321,62 _ FLORA ENERGIA _ PG BANKLINE.pdf | E5: 2026 _ ARQUIVOS DE MOVIMENTO CONTÁBIL/03 - MAR-2026/01. CAIXA BRADESCO/02.MAR/02.03.2026 - R$321,62 _ FLORA ENERGIA _ PG BANKLINE.pdf Pendências AL/BRADESCO/02.03.2026 - R$321,62 _ FLORA ENERGIA _ PG BANKLINE.pdf | F5: Boleto da Flora (via IUGU) com comprovante; o valor confere no texto. Já está na pasta Pendências AL.
A6: AP-10 | B6: Ativo em Processamento | C6: Flora Energia | D6: 17.03.2026 - R$221,38 _ FLORA _ FATURA _ PG BANKLINE.pdf 17.03.2026 - R$221,38 _ FLORA _ FATURA _ PG BANKLINE.pdf | E6: 2026 _ ARQUIVOS DE MOVIMENTO CONTÁBIL/03 - MAR-2026/01. CAIXA BRADESCO/17.MAR/17.03.2026 - R$221,38 _ FLORA _ FATURA _ PG BANKLINE.pdf Pendências AL/BRADESCO/17.03.2026 - R$221,38 _ FLORA _ FATURA _ PG BANKLINE.pdf | F6: Fatura da Flora com comprovante; valor confere no texto. Já está na pasta Pendências AL.
A7: AP-12 | B7: Ativo em Processamento | C7: Prodesc Benfica (cartão) | D7: 10.04.2026 - R$59,80 _ PRODESC BENFICA _ PG CARTAO.pdf | E7: 2026 _ ARQUIVOS DE MOVIMENTO CONTÁBIL/04 - ABR-2026/02. CAIXA AUXILIAR/10.04.2026 - R$59,80 _ PRODESC BENFICA _ PG CARTAO.pdf | F7: NF-e do consumidor nº 125233, R$ 59,80, emitida em 02/03/2026 pela Prodesc Benfica (CNPJ 06.058.769/0001-47). Fatura do cartão de abril existe.
A8: AP-17 | B8: Ativo em Processamento | C8: Dally Boy (caixa) | D8: 18.04.2026 - R$67,00 _ NF762 _ DALLY BOY ATACADAO DE BONES E MEIAS LTDA _ PG ESPÉCIE.pdf | E8: 2026 _ ARQUIVOS DE MOVIMENTO CONTÁBIL/04 - ABR-2026/18.04.2026 - R$67,00 _ NF762 _ DALLY BOY ATACADAO DE BONES E MEIAS LTDA _ PG ESPÉCIE.pdf | F8: NF 762 (Dally Boy Atacadão de Bonés e Meias) paga em espécie, valor confere no texto.
A9: AP-18 | B9: Ativo em Processamento | C9: Prov Telecom | D9: 20.04.2026 - R$99,00 _ PROV TELECOM _ PG BANKLINE.pdf | E9: 2026 _ ARQUIVOS DE MOVIMENTO CONTÁBIL/04 - ABR-2026/01. CAIXA BRADESCO/20.ABRIL/20.04.2026 - R$99,00 _ PROV TELECOM _ PG BANKLINE.pdf | F9: Fatura da Prov Telecom com comprovante; valor confere no texto.
A10: AP-26 | B10: Ativo em Processamento | C10: Patrícia Cantero Soares | D10: 03.08.2026 - R$380,00 _ PATRICIA CANTERO.pdf | E10: 2026 _ ARQUIVOS DE MOVIMENTO CONTÁBIL/08 - AGO-2026/01. CAIXA BRADESCO/03.AGO/03.08.2026 - R$380,00 _ PATRICIA CANTERO.pdf | F10: Arquivo da pasta é uma imagem (nome e valor conferem) e o app já tem NF anexada a esta despesa. Conferir visualmente antes de enviar.
A11: AD-09 | B11: Adiantamentos | C11: RC Design RJ Marketing | D11: 18.12.2026 - R$197,00 _ NF309 _ RC DESIGN RJ MAKETING _ PG BANKLINE.pdf | E11: Pendências AL/BRADESCO/18.12.2026 - R$197,00 _ NF309 _ RC DESIGN RJ MAKETING _ PG BANKLINE.pdf | F11: NF 309 de R$ 197,00 com comprovante (o nome do arquivo tem 2026 por engano; a data é 18/12/2025). Compensa com a NF 309 aberta em fornecedores (FS-12).
A12: AD-17 | B12: Adiantamentos | C12: Patrícia Oliveira da Silva Barreto | D12: NF012 13.12.2024 - R$3.475,63 _ PATRICIA OLIVEIRA DA SILVA BARRETO _ PG BANKLINE.pdf | E12: Pendências AL/PATRICIA OLIVEIRA DA SILVA BARRETO/NFs/NF012 13.12.2024 - R$3.475,63 _ PATRICIA OLIVEIRA DA SILVA BARRETO _ PG BANKLINE.pdf | F12: NF 012 de R$ 3.475,63 com comprovante (em Pendências AL/PATRICIA…).
A13: AD-29 | B13: Adiantamentos | C13: 'Patrícia' (pagamento é de Marco A. Herculano) | D13: 04.07.2026 - R$2.000,00 _ NF010 _ MARCO ANTONIO HERCULANO _ PG BANKLINE.pdf | E13: 2026 _ ARQUIVOS DE MOVIMENTO CONTÁBIL/07 - JUL-2026/01. CAIXA BRADESCO/04.JUL/04.07.2026 - R$2.000,00 _ NF010 _ MARCO ANTONIO HERCULANO _ PG BANKLINE.pdf | F13: O pagamento de 06/07/2026 é do Marco Antonio Herculano, não da Patrícia: NF 010, R$ 2.000,00 (a NF 10 aberta em fornecedores é a mesma). O escritório só precisa reclassificar e compensar (FS-13).
A14: AD-30 | B14: Adiantamentos | C14: Daniel Alves Souza | D14: 27.08.2026 - R$1.090,00 _ NF163 _ DANIEL ALVES SOUZA _ PG BANKLINESOUZ.pdf | E14: 2026 _ ARQUIVOS DE MOVIMENTO CONTÁBIL/08 - AGO-2026/01. CAIXA BRADESCO/27.AGO/27.08.2026 - R$1.090,00 _ NF163 _ DANIEL ALVES SOUZA _ PG BANKLINESOUZ.pdf | F14: NF 163 com comprovante; valor confere.
... A38: FB-25 | B38: Fornecedores de bens | C38: NF 141948: Sendas NF 141948 (2) | D38: 10.09.2026 - R$1.362,38 _ NF141948 _ SENDAS DISTRIBUIDORA _ PG VISA.pdf | E38: 2026 _ ARQUIVOS DE MOVIMENTO CONTÁBIL/09 - SET-2026/A PAGAR _ SETEMBRO/10.09.2026 - R$1.362,38 _ NF141948 _ SENDAS DISTRIBUIDORA _ PG VISA.pdf | F38: Mesma NF 141948 (segunda parte).
A39: FB-27 | B39: Fornecedores de bens | C39: NF 2532: Freecolor Tintas | D39: (documento está no app, não na pasta) | F39: Paga em 23/09/2026 (depois do corte); o app tem boleto e comprovante anexados. Não há arquivo na pasta da Tesouraria.
A40: FS-04 | B40: Fornecedores de serviços | C40: NF 23: Rhaquel Hammerle (NF 23) | D40: 17.06.2025 - R$350,00 _ NF023 _ RHAQUEL HAMMERLE DE ANDRADE _ BOLETO _ PG BANKLINE.pdf 17.06.2025 - R$350,00 _ NF023 _ RHAQUEL HAMMERLE DE ANDRADE _ BOLETO _ PG BANKLINE.pdf | E40: 2025 _ ARQUIVOS DE MOVIMENTO CONTÁBIL/2025 _ 2º TRIMESTRE/06 - JUN-2025 _ MALOTE/01. CAIXA BRADESCO/17.JUN/17.06.2025 - R$350,00 _ NF023 _ RHAQUEL HAMMERLE DE ANDRADE _ BOLETO _ PG BANKLINE.pdf Pendências AL/BRADESCO/17.06.2025 - R$350,00 _ NF023 _ RHAQUEL HAMMERLE DE ANDRADE _ BOLETO _ PG BANKLINE.pdf | F40: NF 023 com boleto e comprovante. Já respondida em jan/2026.
A41: FS-06 | B41: Fornecedores de serviços | C41: NF 166376: Hotelaria Accor | D41: 08.09.2025 - R$445,10 _ NF166376 _ HOTELARIA ACCOR BRASIL SA _ PG ESPÉCIE.pdf | E41: 2025 _ ARQUIVOS DE MOVIMENTO CONTÁBIL/2025 _ 3º TRIMESTRE E OUTUBRO/08 - AGO-2025 _ MALOTE/02. CAIXA AUXILIAR/08.09.2025 - R$445,10 _ NF166376 _ HOTELARIA ACCOR BRASIL SA _ PG ESPÉCIE.pdf | F41: NF 166376 paga em espécie em 08/09/2025 (imagem; nome e valor conferem).
A42: FS-11 | B42: Fornecedores de serviços | C42: NF 5: Honor Música | D42: 06.07.2026 - R$2.000,00 _ NF05 _ HONOR MUSICA & ARTE _ PG ESPÉCIE.pdf | E42: 2026 _ ARQUIVOS DE MOVIMENTO CONTÁBIL/07 - JUL-2026/02. CAIXA AUXILIAR/06.JUL/06.07.2026 - R$2.000,00 _ NF05 _ HONOR MUSICA & ARTE _ PG ESPÉCIE.pdf | F42: NF 05 da Honor Música paga em espécie em 06/07/2026.
A43: FS-12 | B43: Fornecedores de serviços | C43: NF 309: RC Design NF 309 | D43: 18.12.2026 - R$197,00 _ NF309 _ RC DESIGN RJ MAKETING _ PG BANKLINE.pdf | E43: Pendências AL/BRADESCO/18.12.2026 - R$197,00 _ NF309 _ RC DESIGN RJ MAKETING _ PG BANKLINE.pdf | F43: NF 309 com comprovante. Compensa com o adiantamento de 18/12/2025 (AD-09).
A44: FS-13 | B44: Fornecedores de serviços | C44: NF 10: Marco A. Herculano NF 10 | D44: 04.07.2026 - R$2.000,00 _ NF010 _ MARCO ANTONIO HERCULANO _ PG BANKLINE.pdf 05.08.2026 - R$2.000,00 _ NF09 _ MARCO ANTONIO HERCULANO _ PG BANKLINE.pdf | E44: 2026 _ ARQUIVOS DE MOVIMENTO CONTÁBIL/07 - JUL-2026/01. CAIXA BRADESCO/04.JUL/04.07.2026 - R$2.000,00 _ NF010 _ MARCO ANTONIO HERCULANO _ PG BANKLINE.pdf 2026 _ ARQUIVOS DE MOVIMENTO CONTÁBIL/08 - AGO-2026/01. CAIXA BRADESCO/05.AGO/05.08.2026 - R$2.000,00 _ NF09 _ MARCO ANTONIO HERCULANO _ PG BANKLINE.pdf | F44: A NF 10 do Marco é a NF 010 paga em 06/07/2026 (a numeração da pasta não tem zero à esquerda). Compensa com AD-29.
A45: FS-14 | B45: Fornecedores de serviços | C45: NF 3921325: Omiexperience | D45: 30.09.2026 - R$192,04 _ NF03921325 _ OMIE SISTEMAS _ BOLETO.pdf | E45: 2026 _ ARQUIVOS DE MOVIMENTO CONTÁBIL/09 - SET-2026/01. CAIXA BRADESCO/30.SET/30.09.2026 - R$192,04 _ NF03921325 _ OMIE SISTEMAS _ BOLETO.pdf | F45: NF com boleto de R$ 192,04, pago em 30/09/2026 (depois do corte).
A46: FS-17 | B46: Fornecedores de serviços | C46: NF 11: Marco A. Herculano NF 11 | D46: 04.09.2026 - R$2.000,00 _ NF11 _ ASSISTENTE MUSICAL _ MARCO ANTONIO HERCULANO.pdf | E46: 2026 _ ARQUIVOS DE MOVIMENTO CONTÁBIL/09 - SET-2026/01. CAIXA BRADESCO/01.SET/04.09.2026 - R$2.000,00 _ NF11 _ ASSISTENTE MUSICAL _ MARCO ANTONIO HERCULANO.pdf | F46: NF 11 paga em 01/09/2026 (depois do corte).
A47: FS-18 | B47: Fornecedores de serviços | C47: NF 1016: Flávio Inaldo da Silva NF 1016 | D47: 01.09.2026 - R$2.200,00 _ NF1016 _ ASSISTENTE MUSICAL _ FLAVIO INALDO DA SILVA.pdf | E47: 2026 _ ARQUIVOS DE MOVIMENTO CONTÁBIL/09 - SET-2026/01. CAIXA BRADESCO/01.SET/01.09.2026 - R$2.200,00 _ NF1016 _ ASSISTENTE MUSICAL _ FLAVIO INALDO DA SILVA.pdf | F47: NF 1016 paga em 01/09/2026 (depois do corte).
A48: OU-05 | B48: Outras pendências | C48: Extrato Bradesco consolidado de 05/2026 (conta e aplicação) | D48: 05. MAIO.2026 _ EXTRATO UNIFICADO.pdf | E48: Pendências AL/EXTRATOS/05. MAIO.2026 _ EXTRATO UNIFICADO.pdf | F48: Extrato unificado do Bradesco de 05/2026 está em Pendências AL/EXTRATOS (de janeiro a julho/2026).

Sheet Falta decisão da igreja
A1: O que só a igreja pode decidir
A3: ID | B3: Grupo | C3: Pendência | D3: Valor (R$) | E3: O que já se sabe e o que decidir
A4: AP-27 | B4: Ativo em Processamento | C4: Agrottha Pisos (pago a maior) | D4: 540 | E4: NF 051.078 é de R$ 5.400,00 e o pagamento foi de R$ 5.940,00. Decidir: pedir devolução dos R$ 540,00 ou deixar como crédito com a Agrottha.
A5: AD-01 | B5: Adiantamentos | C5: Caio Marcelo Mendes da Silva (tubo de cobre) | D5: 75 | E5: Resposta de jan/2026: tubo de cobre para o ar-condicionado, sem NF. Decidir se aceita a despesa sem NF ou desconta do Caio.
A6: AD-02 | B6: Adiantamentos | C6: Lucio Paulo Paz Barreto (parte dos R$ 1.800 em espécie) | D6: 1253.79 | E6: Resposta de jan/2026: foram R$ 1.800,00 em espécie ao pastor em 08/06/2024 (o app tem esse lançamento na Caixinha). Decidir a natureza (prebenda ou adiantamento) e a data do desconto.
A7: AD-03 | B7: Adiantamentos | C7: Lucio Paulo Paz Barreto (espécie) | D7: 280 | E7: Resposta de jan/2026: o pastor pediu em espécie. Decidir a natureza e a data do desconto.
A8: AD-04 | B8: Adiantamentos | C8: Adiantamento de prebenda a Lucio | D8: 10000 | E8: Resposta de jan/2026: "13º salário???". Existem na pasta adiantamentos do pastor em cheque de R$ 8.000,00 (2024), mas nenhum de R$ 10.000,00. Decidir a data do desconto.
A9: AD-07 | B9: Adiantamentos | C9: Lucio Paulo Paz Barreto (espécie) | D9: 200 | E9: Resposta de jan/2026: o pastor pediu em espécie. Decidir a natureza e a data do desconto.
A10: AD-08 | B10: Adiantamentos | C10: Adiantamento de prebenda a Lucio | D10: 1200 | E10: Adiantamento de prebenda sem resposta. Decidir a data do desconto.
A11: AD-10 | B11: Adiantamentos | C11: Prebenda paga a maior (Lucio) | D11: 1 | E11: Diferença de R$ 1,00 na prebenda de mar/2026. Informar a data de desconto.
A12: AD-11 | B12: Adiantamentos | C12: Prebenda Lucio | D12: 3362 | E12: Prebenda de abr/2026 (R$ 3.362,00). Informar a data de desconto.
A13: AD-14 | B13: Adiantamentos | C13: Prebenda paga a maior (Alexandre) | D13: 1 | E13: Diferença de R$ 1,00 na prebenda de jul/2026 (Alexandre). Informar a data de desconto.
A14: AD-15 | B14: Adiantamentos | C14: Letra do Céu (adiantamento) | D14: 221.4 | E14: Resposta de jan/2026: o pagamento foi duplicado gerando crédito; o fornecedor entregou produtos à irmã Patrícia e não emitiu nota. Decidir: abater em compra futura ou pedir devolução. A Letra do Céu e a Comercial Irmãos Henriques são a mesma empresa.
A15: AD-22 | B15: Adiantamentos | C15: Marcio Nunes da Silva (RPA pago a maior) | D15: 99.89 | E15: RPA de R$ 500,00 existe (imagem); pagamentos de fev: 200 + 100 + 100. Decidir: pedir devolução dos R$ 99,89 ou descontar do próximo RPA.
... A30: OU-04 | B30: Outras pendências | C30: Prebenda a pagar: Lucio, competência 02/2026 | D30: 1018 | E30: Prebenda a pagar de fev/2026 (R$ 1.018,00 de saldo). Em jan/2026 o escritório recebeu, para o saldo de set/2025, a explicação "desconto do dízimo do pastor". Decidir se vale o mesmo aqui.

Sheet Falta documento
A1: O que precisa ser obtido (NF, fatura, bilhete, contrato)
A3: ID | B3: Grupo | C3: Pendência | D3: Valor (R$) | E3: O que falta
A4: AP-01 | B4: Ativo em Processamento | C4: Festa Mania Tijuca (cartão) | D4: 114.95 | E4: A fatura do cartão de jan/2026 existe (prova o gasto), mas a NF da Festa Mania Tijuca não está na pasta. Pedir a NF à loja.
A5: AP-04 | B5: Ativo em Processamento | C5: Latam parc. 1/4 (cartão) | D5: 1541.4 | E5: Nada da Latam em fev/2026. Os dois JPEGs da Latam (R$ 2.392,00 e R$ 269,00) são de setembro, de outra viagem. Falta o bilhete ou recibo.
A6: AP-05 | B6: Ativo em Processamento | C6: S2P inscrição 1/2 (cartão) (1) | D6: 400 | E6: Nada da S2P/E-Inscrição na pasta. Falta o comprovante ou a NF da inscrição (2 inscrições, 2 parcelas de R$ 200,00 cada).
A7: AP-06 | B7: Ativo em Processamento | C7: S2P inscrição 1/2 (cartão) (2) | D7: 400 | E7: Idem AP-05 (segunda inscrição).
A8: AP-07 | B8: Ativo em Processamento | C8: Zupper (cartão) | D8: 232.5 | E8: Nada da Zupper (emitente no app: Kontik Franstur). Falta a NF.
A9: AP-08 | B9: Ativo em Processamento | C9: Commander Digital | D9: 1000 | E9: Só existem a fatura da Commander de 23/01 (R$ 1.000,00) e o pagamento de R$ 500,00 de 27/02. Falta a fatura de fevereiro.
A10: AP-11 | B10: Ativo em Processamento | C10: Commander Digital | D10: 1000 | E10: Nada da Commander em março. Falta a fatura.
A11: AP-13 | B11: Ativo em Processamento | C11: Eletro-Acústica (cartão) | D11: 35 | E11: Nenhum arquivo de R$ 35,00. A NF22423 da pasta é do Lojão do Alcântara, outra compra.
A12: AP-14 | B12: Ativo em Processamento | C12: Prodesc NF 125233 (cartão) | D12: 15.9 | E12: A NF 125233 existe, mas é de R$ 59,80 (linha AP-12), não de R$ 15,90. Os R$ 15,90 são de outra compra, sem NF na pasta. Responder isso ao escritório.
A13: AP-15 | B13: Ativo em Processamento | C13: Ponto Abastec | D13: 295 | E13: Nada da Ponto Abastec na pasta. Falta a NF.
A14: AP-16 | B14: Ativo em Processamento | C14: Cobrança Net Empresa (CBD) | D14: 25.74 | E14: Só há os pagamentos da CBD de 04/05 (R$ 250,00) e 30/07 (R$ 260,00). Falta o documento dos R$ 25,74 de 15/04.
A15: AP-19 | B15: Ativo em Processamento | C15: Atacadão 691 (cartão) | D15: 60.84 | E15: Nenhum arquivo do Atacadão 691/Wms de R$ 60,84. Os arquivos próximos são de outros atacadistas.
... A47: OU-07 | B47: Outras pendências | C47: Saldo divergente do Caixa Auxiliar (R$ 448,92) e do Caixa Envelope (R$ 0,00) | D47: 448.92 | E47: Saldo do Caixa Auxiliar (R$ 448,92) e do Caixa Envelope (R$ 0,00) divergem do escritório. O escritório pede um relatório diário de caixa que não existe na pasta.

Sheet Falta resposta ao escritório
A1: O documento ou a explicação existe; falta responder à contabilidade
A3: ID | B3: Classificação | C3: Pendência | D3: Valor (R$) | E3: O que responder ou completar
A4: AP-03 | B4: Parcialmente Resolvida | C4: Hoteis.com parc. 1/4 (cartão) | D4: 2308.56 | E4: Comprovantes das 4 parcelas (577,14 + 3 × 577,13 = 2.308,53; diferença de R$ 0,03). São imagens: valor e nome conferem, o conteúdo não foi lido. Falta a NF ou o voucher do Hoteis.com.
A5: AD-05 | B5: Falta Resposta à Contabilidade | C5: Caio (pagamento a David Bastos Rocha em espécie) | D5: 203 | E5: Resposta de jan/2026: foi pagamento ao fornecedor David Bastos Rocha, entregue em espécie ao Caio, "já ajustado no Omie". O app também já classifica como David Bastos. Falta só confirmar com o escritório a reclassificação (a NF 9770755 já consta como baixada no escritório).
A6: AD-06 | B6: Parcialmente Resolvida | C6: Telma (compra no cartão pessoal; ajustado p/ Sendas) | D6: 26.77 | E6: NF 39437 da Sendas paga em espécie existe, mas é de R$ 27,88, não de R$ 26,77. Diferença de R$ 1,11 a explicar. Resposta de jan/2026 já cita o arquivo.
A7: AD-16 | B7: Falta Resposta à Contabilidade | C7: Patrícia Oliveira da Silva Barreto | D7: 239.84 | E7: Resposta de jan/2026: "não encontrei pagamento neste valor nesta data". A pasta tem a NF13 de R$ 3.475,63 (22/11/2024); os R$ 239,84 não aparecem em lugar nenhum. A planilha da Patrícia também lista a NF10 (R$ 867,65, 06/11/2024) sem pagamento. Explicar ao escritório.
A8: AD-19 | B8: Parcialmente Resolvida | C8: Marcelo Neves Pimenta (RPA) | D8: 1000 | E8: RPA do pagamento de 24/01 existe (imagem). O app tem dois pagamentos de R$ 1.000,00 (24/01 e 31/01) e só há RPA de um. Confirmar se é duplicidade.
A9: AD-25 | B9: Falta Resposta à Contabilidade | C9: Carlos Eduardo de Santana (competência?) | D9: 720.05 | E9: Comprovantes mensais de R$ 720,05 (07/02, 06/03, 04/04, 07/05/2025). O escritório pergunta se o de 07/05 quita os R$ 540,04 de fev/2025. Responder qual competência cada pagamento cobre.
A10: AD-31 | B10: Parcialmente Resolvida | C10: Patrícia Oliveira da Silva Barreto | D10: 1200 | E10: Arquivo existe, mas é uma imagem sem nome de documento. Conferir se é a NF.
A11: TC-01 | B11: Parcialmente Resolvida | C11: Título de Capitalização Bradesco (proposta 50213007/2): contrato e parcelas | D11: 4577.76 | E11: Conferi no texto os extratos de fev a dez/2023 (todos mostram o débito do título); os extratos de 2024 a 2026 estão na pasta, e há 5 comprovantes avulsos. NÃO existe contrato nem a proposta 50213007/2 na pasta, nem a explicação da mudança de 60 para 90 parcelas.
A12: CT-01 | B12: Parcialmente Resolvida | C12: NF 666342: Frigelar (07x08) | D12: 5635.38 | E12: 7 de 8 parcelas da NF 666342 (Frigelar) com comprovante: jun, ago, set, out, nov, dez/2025 e jan/2026. Falta a parcela 2/8 (jul/2025). Um 8º arquivo com esse número de NF é da Convicção Editora, outra compra.
A13: CT-02 | B13: Parcialmente Resolvida | C13: NF 171742: BMB Material de Construção (06x06) | D13: 4241.38 | E13: 4 de 6 parcelas (set a dez/2025). O nº da NF nos arquivos é 141742, o escritório diz 171742 (um dos dois está digitado errado). Faltam as parcelas de jan e fev/2026.
A14: CT-07 | B14: Parcialmente Resolvida | C14: NF 1931: G2B Comércio (05x06) = Prisma | D14: 519.98 | E14: 6 parcelas de R$ 86,66 com NF, mas a NF nos arquivos é a 5362 da Prisma, e o escritório fala da NF 1931 da G2B. Confirmar se é a mesma compra.
A15: FB-16 | B15: Parcialmente Resolvida | C15: NF 11703: Handhelp Soluções | D15: 2265 | E15: Há 2 pagamentos (16/07 e 13/08) e a NF 11701; a NF 11703 (R$ 2.265,00) não está na pasta, e falta o pagamento de 29/06 (R$ 852,69).
... A22: OU-06 | B22: Falta Resposta à Contabilidade | C22: Contas correntes de Missões (Mundiais R$ 7.339,88 e Nacionais R$ 972,83) | D22: 8312.71 | E22: Contas correntes de Missões (R$ 7.339,88 e R$ 972,83): os repasses estão na pasta, mas o saldo precisa ser explicado ao escritório.
